Workbook
Name inception_date: Census!$Z$2

Sheet Census
A1: SN | B1: Name | C1: Relation | D1: Gender | E1: Marital | F1: Member type | G1: Date of Birth (DD/MM/YYYY) | H1: Nationality | I1: Category | J1: Age | K1: Age Band | L1: Health UW Loading | M1: Life UW Loading | N1: PA UW Loading | O1: Eligible for | R1: Control | S1: CHECK FORMAT INPUT If RED Check & input again | Z1: Effective date | AA1: Census Check | AB1: CHK Name | AC1: CHK Gender | AD1: CHK relation | AE1: CHK Marital | AF1: CHK DOB | AG1: CHK Plan | AH1: Check Final | AJ1: Age band Reference Table
A2: 1 | J2: =IFERROR(IF(G2="","",ROUNDDOWN(IF($G2="","",(inception_date-$G2)/365.25),0)),0) | K2: =IF(I2="","",IF($AM$3=1,IFERROR(IF(J2=FALSE,"",VLOOKUP(J2,$AJ$1:$AK$18,2,1)),""),IFERROR(IF(J2 = "FALSE","",VLOOKUP(J2,#REF!,2,TRUE)),""))) | O2: =IF(C2="","",IF(R2=1,"Yes","No")) | P2: =IFERROR(IF(C2="","",IF(AND(Census!C2="E",Census!J2>=18,Census!J2<=65),"Yes","No")),"ERROR") | Q2: =IFERROR(IF(C2="","",IF(AND(Census!C2="E",Census!J2>=18,Census!J2<=64),"Yes","No")),"ERROR") | R2: =IF(OR(AB2<>1,AC2<>1,AD2<>1,AF2<>1,AE2<>1,AG2<>1),-1,1) -> -1 | S2: =AB2 -> 0 | T2: =AC2 -> 0 | U2: =AD2 -> 0 | V2: =AE2 -> 0 | W2: =AF2 -> -1 | X2: =AG2 -> 0 | Z2: 45708 | AA2: =IF((COUNTIF(AH2:AH201,0)+COUNTIF(AH2:AH201,-1))>MIN(COUNTIF(AE2:AE201,0),COUNTIF(AF2:AF201,-1),COUNTIF(AG2:AG201,0)),0,1) -> 1 | AB2: =IFERROR(IF(OR(B2=0,B2=""),0,1),0) -> 0 | AC2: =IFERROR(IF(OR(C2="S",C2="D"),IF(AND(C2="D",D2="F"),1,IF(AND(C2="S",D2="M"),1,0)),IF(OR(C2="W",C2="H"),IF(OR(AND(C2="W",D2="F"),AND(C2="H",D2="M")),1,),IF(OR(D2="M",D2="F"),1,0))),0) -> 0 | AD2: =IFERROR(IF(OR(C2="E",C2="W",C2="H"),1,IF(C2 = "S",IF(D2="M",1,0),IF(D2 = "F",1,0))),0) -> 0 | AE2: =IFERROR(IF(OR(E2="M",E2="S"),IF(E2="M",IF(OR(C2="S",C2 = "D"),0,1),IF(OR(C2="W",C2="H"),0,1)),0),0) -> 0 | AF2: =IF(G2="",-1,IF(AND(G2<=TODAY(),ISNUMBER(DATE(YEAR(G2),MONTH(G2),DAY(G2)))),IF(AND(OR(C2="S",C2="D"),J2>24),-1,1),-1)) -> -1 | AG2: =IF(OR(I2="CAT 1",I2="CAT 2",I2="CAT 3",I2="CAT 4"),1,0) -> 0 | AH2: =PRODUCT(AF2:AG2)*AE2 -> 0 | AJ2: 0 | AK2: 0-4
A3: 2 | J3: =IFERROR(IF(G3="","",ROUNDDOWN(IF($G3="","",(inception_date-$G3)/365.25),0)),0) | K3: =IF(I3="","",IF($AM$3=1,IFERROR(IF(J3=FALSE,"",VLOOKUP(J3,$AJ$1:$AK$18,2,1)),""),IFERROR(IF(J3 = "FALSE","",VLOOKUP(J3,#REF!,2,TRUE)),""))) | O3: =IF(C3="","",IF(R3=1,"Yes","No")) | P3: =IFERROR(IF(C3="","",IF(AND(Census!C3="E",Census!J3>=18,Census!J3<=65),"Yes","No")),"ERROR") | Q3: =IFERROR(IF(C3="","",IF(AND(Census!C3="E",Census!J3>=18,Census!J3<=64),"Yes","No")),"ERROR") | R3: =IF(OR(AB3<>1,AC3<>1,AD3<>1,AF3<>1,AE3<>1,AG3<>1),-1,1) -> -1 | S3: =AB3 -> 0 | T3: =AC3 -> 0 | U3: =AD3 -> 0 | V3: =AE3 -> 0 | W3: =AF3 -> -1 | X3: =AG3 -> 0 | AB3: =IFERROR(IF(OR(B3=0,B3=""),0,1),0) -> 0 | AC3: =IFERROR(IF(OR(C3="S",C3="D"),IF(AND(C3="D",D3="F"),1,IF(AND(C3="S",D3="M"),1,0)),IF(OR(C3="W",C3="H"),IF(OR(AND(C3="W",D3="F"),AND(C3="H",D3="M")),1,),IF(OR(D3="M",D3="F"),1,0))),0) -> 0 | AD3: =IFERROR(IF(OR(C3="E",C3="W",C3="H"),1,IF(C3 = "S",IF(D3="M",1,0),IF(D3 = "F",1,0))),0) -> 0 | AE3: =IFERROR(IF(OR(E3="M",E3="S"),IF(E3="M",IF(OR(C3="S",C3 = "D"),0,1),IF(OR(C3="W",C3="H"),0,1)),0),0) -> 0 | AF3: =IF(G3="",-1,IF(AND(G3<=TODAY(),ISNUMBER(DATE(YEAR(G3),MONTH(G3),DAY(G3)))),IF(AND(OR(C3="S",C3="D"),J3>24),-1,1),-1)) -> -1 | AG3: =IF(OR(I3="CAT 1",I3="CAT 2",I3="CAT 3",I3="CAT 4"),1,0) -> 0 | AH3: =PRODUCT(AF3:AG3)*AE3 -> 0 | AI3: =YEAR(TODAY()) -> 2025 | AJ3: =AJ2+5 -> 5 | AK3: 5-9 | AM3: 1
A4: 3 | J4: =IFERROR(IF(G4="","",ROUNDDOWN(IF($G4="","",(inception_date-$G4)/365.25),0)),0) | K4: =IF(I4="","",IF($AM$3=1,IFERROR(IF(J4=FALSE,"",VLOOKUP(J4,$AJ$1:$AK$18,2,1)),""),IFERROR(IF(J4 = "FALSE","",VLOOKUP(J4,#REF!,2,TRUE)),""))) | O4: =IF(C4="","",IF(R4=1,"Yes","No")) | P4: =IFERROR(IF(C4="","",IF(AND(Census!C4="E",Census!J4>=18,Census!J4<=65),"Yes","No")),"ERROR") | Q4: =IFERROR(IF(C4="","",IF(AND(Census!C4="E",Census!J4>=18,Census!J4<=64),"Yes","No")),"ERROR") | R4: =IF(OR(AB4<>1,AC4<>1,AD4<>1,AF4<>1,AE4<>1,AG4<>1),-1,1) -> -1 | S4: =AB4 -> 0 | T4: =AC4 -> 0 | U4: =AD4 -> 0 | V4: =AE4 -> 0 | W4: =AF4 -> -1 | X4: =AG4 -> 0 | AB4: =IFERROR(IF(OR(B4=0,B4=""),0,1),0) -> 0 | AC4: =IFERROR(IF(OR(C4="S",C4="D"),IF(AND(C4="D",D4="F"),1,IF(AND(C4="S",D4="M"),1,0)),IF(OR(C4="W",C4="H"),IF(OR(AND(C4="W",D4="F"),AND(C4="H",D4="M")),1,),IF(OR(D4="M",D4="F"),1,0))),0) -> 0 | AD4: =IFERROR(IF(OR(C4="E",C4="W",C4="H"),1,IF(C4 = "S",IF(D4="M",1,0),IF(D4 = "F",1,0))),0) -> 0 | AE4: =IFERROR(IF(OR(E4="M",E4="S"),IF(E4="M",IF(OR(C4="S",C4 = "D"),0,1),IF(OR(C4="W",C4="H"),0,1)),0),0) -> 0 | AF4: =IF(G4="",-1,IF(AND(G4<=TODAY(),ISNUMBER(DATE(YEAR(G4),MONTH(G4),DAY(G4)))),IF(AND(OR(C4="S",C4="D"),J4>24),-1,1),-1)) -> -1 | AG4: =IF(OR(I4="CAT 1",I4="CAT 2",I4="CAT 3",I4="CAT 4"),1,0) -> 0 | AH4: =PRODUCT(AF4:AG4)*AE4 -> 0 | AJ4: =AJ3+5 -> 10 | AK4: 10-14
A5: 4 | J5: =IFERROR(IF(G5="","",ROUNDDOWN(IF($G5="","",(inception_date-$G5)/365.25),0)),0) | K5: =IF(I5="","",IF($AM$3=1,IFERROR(IF(J5=FALSE,"",VLOOKUP(J5,$AJ$1:$AK$18,2,1)),""),IFERROR(IF(J5 = "FALSE","",VLOOKUP(J5,#REF!,2,TRUE)),""))) | O5: =IF(C5="","",IF(R5=1,"Yes","No")) | P5: =IFERROR(IF(C5="","",IF(AND(Census!C5="E",Census!J5>=18,Census!J5<=65),"Yes","No")),"ERROR") | Q5: =IFERROR(IF(C5="","",IF(AND(Census!C5="E",Census!J5>=18,Census!J5<=64),"Yes","No")),"ERROR") | R5: =IF(OR(AB5<>1,AC5<>1,AD5<>1,AF5<>1,AE5<>1,AG5<>1),-1,1) -> -1 | S5: =AB5 -> 0 | T5: =AC5 -> 0 | U5: =AD5 -> 0 | V5: =AE5 -> 0 | W5: =AF5 -> -1 | X5: =AG5 -> 0 | AB5: =IFERROR(IF(OR(B5=0,B5=""),0,1),0) -> 0 | AC5: =IFERROR(IF(OR(C5="S",C5="D"),IF(AND(C5="D",D5="F"),1,IF(AND(C5="S",D5="M"),1,0)),IF(OR(C5="W",C5="H"),IF(OR(AND(C5="W",D5="F"),AND(C5="H",D5="M")),1,),IF(OR(D5="M",D5="F"),1,0))),0) -> 0 | AD5: =IFERROR(IF(OR(C5="E",C5="W",C5="H"),1,IF(C5 = "S",IF(D5="M",1,0),IF(D5 = "F",1,0))),0) -> 0 | AE5: =IFERROR(IF(OR(E5="M",E5="S"),IF(E5="M",IF(OR(C5="S",C5 = "D"),0,1),IF(OR(C5="W",C5="H"),0,1)),0),0) -> 0 | AF5: =IF(G5="",-1,IF(AND(G5<=TODAY(),ISNUMBER(DATE(YEAR(G5),MONTH(G5),DAY(G5)))),IF(AND(OR(C5="S",C5="D"),J5>24),-1,1),-1)) -> -1 | AG5: =IF(OR(I5="CAT 1",I5="CAT 2",I5="CAT 3",I5="CAT 4"),1,0) -> 0 | AH5: =PRODUCT(AF5:AG5)*AE5 -> 0 | AJ5: =AJ4+5 -> 15 | AK5: 15-19
A6: 5 | J6: =IFERROR(IF(G6="","",ROUNDDOWN(IF($G6="","",(inception_date-$G6)/365.25),0)),0) | K6: =IF(I6="","",IF($AM$3=1,IFERROR(IF(J6=FALSE,"",VLOOKUP(J6,$AJ$1:$AK$18,2,1)),""),IFERROR(IF(J6 = "FALSE","",VLOOKUP(J6,#REF!,2,TRUE)),""))) | O6: =IF(C6="","",IF(R6=1,"Yes","No")) | P6: =IFERROR(IF(C6="","",IF(AND(Census!C6="E",Census!J6>=18,Census!J6<=65),"Yes","No")),"ERROR") | Q6: =IFERROR(IF(C6="","",IF(AND(Census!C6="E",Census!J6>=18,Census!J6<=64),"Yes","No")),"ERROR") | R6: =IF(OR(AB6<>1,AC6<>1,AD6<>1,AF6<>1,AE6<>1,AG6<>1),-1,1) -> -1 | S6: =AB6 -> 0 | T6: =AC6 -> 0 | U6: =AD6 -> 0 | V6: =AE6 -> 0 | W6: =AF6 -> -1 | X6: =AG6 -> 0 | AB6: =IFERROR(IF(OR(B6=0,B6=""),0,1),0) -> 0 | AC6: =IFERROR(IF(OR(C6="S",C6="D"),IF(AND(C6="D",D6="F"),1,IF(AND(C6="S",D6="M"),1,0)),IF(OR(C6="W",C6="H"),IF(OR(AND(C6="W",D6="F"),AND(C6="H",D6="M")),1,),IF(OR(D6="M",D6="F"),1,0))),0) -> 0 | AD6: =IFERROR(IF(OR(C6="E",C6="W",C6="H"),1,IF(C6 = "S",IF(D6="M",1,0),IF(D6 = "F",1,0))),0) -> 0 | AE6: =IFERROR(IF(OR(E6="M",E6="S"),IF(E6="M",IF(OR(C6="S",C6 = "D"),0,1),IF(OR(C6="W",C6="H"),0,1)),0),0) -> 0 | AF6: =IF(G6="",-1,IF(AND(G6<=TODAY(),ISNUMBER(DATE(YEAR(G6),MONTH(G6),DAY(G6)))),IF(AND(OR(C6="S",C6="D"),J6>24),-1,1),-1)) -> -1 | AG6: =IF(OR(I6="CAT 1",I6="CAT 2",I6="CAT 3",I6="CAT 4"),1,0) -> 0 | AH6: =PRODUCT(AF6:AG6)*AE6 -> 0 | AJ6: =AJ5+5 -> 20 | AK6: 20-24 | AM6: date min | AN6: =AN7-(99*365.25) -> 9553.25
A7: 6 | J7: =IFERROR(IF(G7="","",ROUNDDOWN(IF($G7="","",(inception_date-$G7)/365.25),0)),0) | K7: =IF(I7="","",IF($AM$3=1,IFERROR(IF(J7=FALSE,"",VLOOKUP(J7,$AJ$1:$AK$18,2,1)),""),IFERROR(IF(J7 = "FALSE","",VLOOKUP(J7,#REF!,2,TRUE)),""))) | O7: =IF(C7="","",IF(R7=1,"Yes","No")) | P7: =IFERROR(IF(C7="","",IF(AND(Census!C7="E",Census!J7>=18,Census!J7<=65),"Yes","No")),"ERROR") | Q7: =IFERROR(IF(C7="","",IF(AND(Census!C7="E",Census!J7>=18,Census!J7<=64),"Yes","No")),"ERROR") | R7: =IF(OR(AB7<>1,AC7<>1,AD7<>1,AF7<>1,AE7<>1,AG7<>1),-1,1) -> -1 | S7: =AB7 -> 0 | T7: =AC7 -> 0 | U7: =AD7 -> 0 | V7: =AE7 -> 0 | W7: =AF7 -> -1 | X7: =AG7 -> 0 | AB7: =IFERROR(IF(OR(B7=0,B7=""),0,1),0) -> 0 | AC7: =IFERROR(IF(OR(C7="S",C7="D"),IF(AND(C7="D",D7="F"),1,IF(AND(C7="S",D7="M"),1,0)),IF(OR(C7="W",C7="H"),IF(OR(AND(C7="W",D7="F"),AND(C7="H",D7="M")),1,),IF(OR(D7="M",D7="F"),1,0))),0) -> 0 | AD7: =IFERROR(IF(OR(C7="E",C7="W",C7="H"),1,IF(C7 = "S",IF(D7="M",1,0),IF(D7 = "F",1,0))),0) -> 0 | AE7: =IFERROR(IF(OR(E7="M",E7="S"),IF(E7="M",IF(OR(C7="S",C7 = "D"),0,1),IF(OR(C7="W",C7="H"),0,1)),0),0) -> 0 | AF7: =IF(G7="",-1,IF(AND(G7<=TODAY(),ISNUMBER(DATE(YEAR(G7),MONTH(G7),DAY(G7)))),IF(AND(OR(C7="S",C7="D"),J7>24),-1,1),-1)) -> -1 | AG7: =IF(OR(I7="CAT 1",I7="CAT 2",I7="CAT 3",I7="CAT 4"),1,0) -> 0 | AH7: =PRODUCT(AF7:AG7)*AE7 -> 0 | AJ7: =AJ6+5 -> 25 | AK7: 25-29 | AM7: date max | AN7: =TODAY() -> 45713
A8: 7 | J8: =IFERROR(IF(G8="","",ROUNDDOWN(IF($G8="","",(inception_date-$G8)/365.25),0)),0) | K8: =IF(I8="","",IF($AM$3=1,IFERROR(IF(J8=FALSE,"",VLOOKUP(J8,$AJ$1:$AK$18,2,1)),""),IFERROR(IF(J8 = "FALSE","",VLOOKUP(J8,#REF!,2,TRUE)),""))) | O8: =IF(C8="","",IF(R8=1,"Yes","No")) | P8: =IFERROR(IF(C8="","",IF(AND(Census!C8="E",Census!J8>=18,Census!J8<=65),"Yes","No")),"ERROR") | Q8: =IFERROR(IF(C8="","",IF(AND(Census!C8="E",Census!J8>=18,Census!J8<=64),"Yes","No")),"ERROR") | R8: =IF(OR(AB8<>1,AC8<>1,AD8<>1,AF8<>1,AE8<>1,AG8<>1),-1,1) -> -1 | S8: =AB8 -> 0 | T8: =AC8 -> 0 | U8: =AD8 -> 0 | V8: =AE8 -> 0 | W8: =AF8 -> -1 | X8: =AG8 -> 0 | AB8: =IFERROR(IF(OR(B8=0,B8=""),0,1),0) -> 0 | AC8: =IFERROR(IF(OR(C8="S",C8="D"),IF(AND(C8="D",D8="F"),1,IF(AND(C8="S",D8="M"),1,0)),IF(OR(C8="W",C8="H"),IF(OR(AND(C8="W",D8="F"),AND(C8="H",D8="M")),1,),IF(OR(D8="M",D8="F"),1,0))),0) -> 0 | AD8: =IFERROR(IF(OR(C8="E",C8="W",C8="H"),1,IF(C8 = "S",IF(D8="M",1,0),IF(D8 = "F",1,0))),0) -> 0 | AE8: =IFERROR(IF(OR(E8="M",E8="S"),IF(E8="M",IF(OR(C8="S",C8 = "D"),0,1),IF(OR(C8="W",C8="H"),0,1)),0),0) -> 0 | AF8: =IF(G8="",-1,IF(AND(G8<=TODAY(),ISNUMBER(DATE(YEAR(G8),MONTH(G8),DAY(G8)))),IF(AND(OR(C8="S",C8="D"),J8>24),-1,1),-1)) -> -1 | AG8: =IF(OR(I8="CAT 1",I8="CAT 2",I8="CAT 3",I8="CAT 4"),1,0) -> 0 | AH8: =PRODUCT(AF8:AG8)*AE8 -> 0 | AJ8: =AJ7+5 -> 30 | AK8: 30-34
A9: 8 | J9: =IFERROR(IF(G9="","",ROUNDDOWN(IF($G9="","",(inception_date-$G9)/365.25),0)),0) | K9: =IF(I9="","",IF($AM$3=1,IFERROR(IF(J9=FALSE,"",VLOOKUP(J9,$AJ$1:$AK$18,2,1)),""),IFERROR(IF(J9 = "FALSE","",VLOOKUP(J9,#REF!,2,TRUE)),""))) | O9: =IF(C9="","",IF(R9=1,"Yes","No")) | P9: =IFERROR(IF(C9="","",IF(AND(Census!C9="E",Census!J9>=18,Census!J9<=65),"Yes","No")),"ERROR") | Q9: =IFERROR(IF(C9="","",IF(AND(Census!C9="E",Census!J9>=18,Census!J9<=64),"Yes","No")),"ERROR") | R9: =IF(OR(AB9<>1,AC9<>1,AD9<>1,AF9<>1,AE9<>1,AG9<>1),-1,1) -> -1 | S9: =AB9 -> 0 | T9: =AC9 -> 0 | U9: =AD9 -> 0 | V9: =AE9 -> 0 | W9: =AF9 -> -1 | X9: =AG9 -> 0 | AB9: =IFERROR(IF(OR(B9=0,B9=""),0,1),0) -> 0 | AC9: =IFERROR(IF(OR(C9="S",C9="D"),IF(AND(C9="D",D9="F"),1,IF(AND(C9="S",D9="M"),1,0)),IF(OR(C9="W",C9="H"),IF(OR(AND(C9="W",D9="F"),AND(C9="H",D9="M")),1,),IF(OR(D9="M",D9="F"),1,0))),0) -> 0 | AD9: =IFERROR(IF(OR(C9="E",C9="W",C9="H"),1,IF(C9 = "S",IF(D9="M",1,0),IF(D9 = "F",1,0))),0) -> 0 | AE9: =IFERROR(IF(OR(E9="M",E9="S"),IF(E9="M",IF(OR(C9="S",C9 = "D"),0,1),IF(OR(C9="W",C9="H"),0,1)),0),0) -> 0 | AF9: =IF(G9="",-1,IF(AND(G9<=TODAY(),ISNUMBER(DATE(YEAR(G9),MONTH(G9),DAY(G9)))),IF(AND(OR(C9="S",C9="D"),J9>24),-1,1),-1)) -> -1 | AG9: =IF(OR(I9="CAT 1",I9="CAT 2",I9="CAT 3",I9="CAT 4"),1,0) -> 0 | AH9: =PRODUCT(AF9:AG9)*AE9 -> 0 | AJ9: =AJ8+5 -> 35 | AK9: 35-39
A10: 9 | J10: =IFERROR(IF(G10="","",ROUNDDOWN(IF($G10="","",(inception_date-$G10)/365.25),0)),0) | K10: =IF(I10="","",IF($AM$3=1,IFERROR(IF(J10=FALSE,"",VLOOKUP(J10,$AJ$1:$AK$18,2,1)),""),IFERROR(IF(J10 = "FALSE","",VLOOKUP(J10,#REF!,2,TRUE)),""))) | O10: =IF(C10="","",IF(R10=1,"Yes","No")) | P10: =IFERROR(IF(C10="","",IF(AND(Census!C10="E",Census!J10>=18,Census!J10<=65),"Yes","No")),"ERROR") | Q10: =IFERROR(IF(C10="","",IF(AND(Census!C10="E",Census!J10>=18,Census!J10<=64),"Yes","No")),"ERROR") | R10: =IF(OR(AB10<>1,AC10<>1,AD10<>1,AF10<>1,AE10<>1,AG10<>1),-1,1) -> -1 | S10: =AB10 -> 0 | T10: =AC10 -> 0 | U10: =AD10 -> 0 | V10: =AE10 -> 0 | W10: =AF10 -> -1 | X10: =AG10 -> 0 | AB10: =IFERROR(IF(OR(B10=0,B10=""),0,1),0) -> 0 | AC10: =IFERROR(IF(OR(C10="S",C10="D"),IF(AND(C10="D",D10="F"),1,IF(AND(C10="S",D10="M"),1,0)),IF(OR(C10="W",C10="H"),IF(OR(AND(C10="W",D10="F"),AND(C10="H",D10="M")),1,),IF(OR(D10="M",D10="F"),1,0))),0) -> 0 | AD10: =IFERROR(IF(OR(C10="E",C10="W",C10="H"),1,IF(C10 = "S",IF(D10="M",1,0),IF(D10 = "F",1,0))),0) -> 0 | AE10: =IFERROR(IF(OR(E10="M",E10="S"),IF(E10="M",IF(OR(C10="S",C10 = "D"),0,1),IF(OR(C10="W",C10="H"),0,1)),0),0) -> 0 | AF10: =IF(G10="",-1,IF(AND(G10<=TODAY(),ISNUMBER(DATE(YEAR(G10),MONTH(G10),DAY(G10)))),IF(AND(OR(C10="S",C10="D"),J10>24),-1,1),-1)) -> -1 | AG10: =IF(OR(I10="CAT 1",I10="CAT 2",I10="CAT 3",I10="CAT 4"),1,0) -> 0 | AH10: =PRODUCT(AF10:AG10)*AE10 -> 0 | AJ10: =AJ9+5 -> 40 | AK10: 40-44
A11: 10 | J11: =IFERROR(IF(G11="","",ROUNDDOWN(IF($G11="","",(inception_date-$G11)/365.25),0)),0) | K11: =IF(I11="","",IF($AM$3=1,IFERROR(IF(J11=FALSE,"",VLOOKUP(J11,$AJ$1:$AK$18,2,1)),""),IFERROR(IF(J11 = "FALSE","",VLOOKUP(J11,#REF!,2,TRUE)),""))) | O11: =IF(C11="","",IF(R11=1,"Yes","No")) | P11: =IFERROR(IF(C11="","",IF(AND(Census!C11="E",Census!J11>=18,Census!J11<=65),"Yes","No")),"ERROR") | Q11: =IFERROR(IF(C11="","",IF(AND(Census!C11="E",Census!J11>=18,Census!J11<=64),"Yes","No")),"ERROR") | R11: =IF(OR(AB11<>1,AC11<>1,AD11<>1,AF11<>1,AE11<>1,AG11<>1),-1,1) -> -1 | S11: =AB11 -> 0 | T11: =AC11 -> 0 | U11: =AD11 -> 0 | V11: =AE11 -> 0 | W11: =AF11 -> -1 | X11: =AG11 -> 0 | AB11: =IFERROR(IF(OR(B11=0,B11=""),0,1),0) -> 0 | AC11: =IFERROR(IF(OR(C11="S",C11="D"),IF(AND(C11="D",D11="F"),1,IF(AND(C11="S",D11="M"),1,0)),IF(OR(C11="W",C11="H"),IF(OR(AND(C11="W",D11="F"),AND(C11="H",D11="M")),1,),IF(OR(D11="M",D11="F"),1,0))),0) -> 0 | AD11: =IFERROR(IF(OR(C11="E",C11="W",C11="H"),1,IF(C11 = "S",IF(D11="M",1,0),IF(D11 = "F",1,0))),0) -> 0 | AE11: =IFERROR(IF(OR(E11="M",E11="S"),IF(E11="M",IF(OR(C11="S",C11 = "D"),0,1),IF(OR(C11="W",C11="H"),0,1)),0),0) -> 0 | AF11: =IF(G11="",-1,IF(AND(G11<=TODAY(),ISNUMBER(DATE(YEAR(G11),MONTH(G11),DAY(G11)))),IF(AND(OR(C11="S",C11="D"),J11>24),-1,1),-1)) -> -1 | AG11: =IF(OR(I11="CAT 1",I11="CAT 2",I11="CAT 3",I11="CAT 4"),1,0) -> 0 | AH11: =PRODUCT(AF11:AG11)*AE11 -> 0 | AJ11: =AJ10+5 -> 45 | AK11: 45-49
A12: 11 | J12: =IFERROR(IF(G12="","",ROUNDDOWN(IF($G12="","",(inception_date-$G12)/365.25),0)),0) | K12: =IF(I12="","",IF($AM$3=1,IFERROR(IF(J12=FALSE,"",VLOOKUP(J12,$AJ$1:$AK$18,2,1)),""),IFERROR(IF(J12 = "FALSE","",VLOOKUP(J12,#REF!,2,TRUE)),""))) | O12: =IF(C12="","",IF(R12=1,"Yes","No")) | P12: =IFERROR(IF(C12="","",IF(AND(Census!C12="E",Census!J12>=18,Census!J12<=65),"Yes","No")),"ERROR") | Q12: =IFERROR(IF(C12="","",IF(AND(Census!C12="E",Census!J12>=18,Census!J12<=64),"Yes","No")),"ERROR") | R12: =IF(OR(AB12<>1,AC12<>1,AD12<>1,AF12<>1,AE12<>1,AG12<>1),-1,1) -> -1 | S12: =AB12 -> 0 | T12: =AC12 -> 0 | U12: =AD12 -> 0 | V12: =AE12 -> 0 | W12: =AF12 -> -1 | X12: =AG12 -> 0 | AB12: =IFERROR(IF(OR(B12=0,B12=""),0,1),0) -> 0 | AC12: =IFERROR(IF(OR(C12="S",C12="D"),IF(AND(C12="D",D12="F"),1,IF(AND(C12="S",D12="M"),1,0)),IF(OR(C12="W",C12="H"),IF(OR(AND(C12="W",D12="F"),AND(C12="H",D12="M")),1,),IF(OR(D12="M",D12="F"),1,0))),0) -> 0 | AD12: =IFERROR(IF(OR(C12="E",C12="W",C12="H"),1,IF(C12 = "S",IF(D12="M",1,0),IF(D12 = "F",1,0))),0) -> 0 | AE12: =IFERROR(IF(OR(E12="M",E12="S"),IF(E12="M",IF(OR(C12="S",C12 = "D"),0,1),IF(OR(C12="W",C12="H"),0,1)),0),0) -> 0 | AF12: =IF(G12="",-1,IF(AND(G12<=TODAY(),ISNUMBER(DATE(YEAR(G12),MONTH(G12),DAY(G12)))),IF(AND(OR(C12="S",C12="D"),J12>24),-1,1),-1)) -> -1 | AG12: =IF(OR(I12="CAT 1",I12="CAT 2",I12="CAT 3",I12="CAT 4"),1,0) -> 0 | AH12: =PRODUCT(AF12:AG12)*AE12 -> 0 | AJ12: =AJ11+5 -> 50 | AK12: 50-54
A13: 12 | J13: =IFERROR(IF(G13="","",ROUNDDOWN(IF($G13="","",(inception_date-$G13)/365.25),0)),0) | K13: =IF(I13="","",IF($AM$3=1,IFERROR(IF(J13=FALSE,"",VLOOKUP(J13,$AJ$1:$AK$18,2,1)),""),IFERROR(IF(J13 = "FALSE","",VLOOKUP(J13,#REF!,2,TRUE)),""))) | O13: =IF(C13="","",IF(R13=1,"Yes","No")) | P13: =IFERROR(IF(C13="","",IF(AND(Census!C13="E",Census!J13>=18,Census!J13<=65),"Yes","No")),"ERROR") | Q13: =IFERROR(IF(C13="","",IF(AND(Census!C13="E",Census!J13>=18,Census!J13<=64),"Yes","No")),"ERROR") | R13: =IF(OR(AB13<>1,AC13<>1,AD13<>1,AF13<>1,AE13<>1,AG13<>1),-1,1) -> -1 | S13: =AB13 -> 0 | T13: =AC13 -> 0 | U13: =AD13 -> 0 | V13: =AE13 -> 0 | W13: =AF13 -> -1 | X13: =AG13 -> 0 | AB13: =IFERROR(IF(OR(B13=0,B13=""),0,1),0) -> 0 | AC13: =IFERROR(IF(OR(C13="S",C13="D"),IF(AND(C13="D",D13="F"),1,IF(AND(C13="S",D13="M"),1,0)),IF(OR(C13="W",C13="H"),IF(OR(AND(C13="W",D13="F"),AND(C13="H",D13="M")),1,),IF(OR(D13="M",D13="F"),1,0))),0) -> 0 | AD13: =IFERROR(IF(OR(C13="E",C13="W",C13="H"),1,IF(C13 = "S",IF(D13="M",1,0),IF(D13 = "F",1,0))),0) -> 0 | AE13: =IFERROR(IF(OR(E13="M",E13="S"),IF(E13="M",IF(OR(C13="S",C13 = "D"),0,1),IF(OR(C13="W",C13="H"),0,1)),0),0) -> 0 | AF13: =IF(G13="",-1,IF(AND(G13<=TODAY(),ISNUMBER(DATE(YEAR(G13),MONTH(G13),DAY(G13)))),IF(AND(OR(C13="S",C13="D"),J13>24),-1,1),-1)) -> -1 | AG13: =IF(OR(I13="CAT 1",I13="CAT 2",I13="CAT 3",I13="CAT 4"),1,0) -> 0 | AH13: =PRODUCT(AF13:AG13)*AE13 -> 0 | AJ13: =AJ12+5 -> 55 | AK13: 55-59
A14: 13 | J14: =IFERROR(IF(G14="","",ROUNDDOWN(IF($G14="","",(inception_date-$G14)/365.25),0)),0) | K14: =IF(I14="","",IF($AM$3=1,IFERROR(IF(J14=FALSE,"",VLOOKUP(J14,$AJ$1:$AK$18,2,1)),""),IFERROR(IF(J14 = "FALSE","",VLOOKUP(J14,#REF!,2,TRUE)),""))) | O14: =IF(C14="","",IF(R14=1,"Yes","No")) | P14: =IFERROR(IF(C14="","",IF(AND(Census!C14="E",Census!J14>=18,Census!J14<=65),"Yes","No")),"ERROR") | Q14: =IFERROR(IF(C14="","",IF(AND(Census!C14="E",Census!J14>=18,Census!J14<=64),"Yes","No")),"ERROR") | R14: =IF(OR(AB14<>1,AC14<>1,AD14<>1,AF14<>1,AE14<>1,AG14<>1),-1,1) -> -1 | S14: =AB14 -> 0 | T14: =AC14 -> 0 | U14: =AD14 -> 0 | V14: =AE14 -> 0 | W14: =AF14 -> -1 | X14: =AG14 -> 0 | AB14: =IFERROR(IF(OR(B14=0,B14=""),0,1),0) -> 0 | AC14: =IFERROR(IF(OR(C14="S",C14="D"),IF(AND(C14="D",D14="F"),1,IF(AND(C14="S",D14="M"),1,0)),IF(OR(C14="W",C14="H"),IF(OR(AND(C14="W",D14="F"),AND(C14="H",D14="M")),1,),IF(OR(D14="M",D14="F"),1,0))),0) -> 0 | AD14: =IFERROR(IF(OR(C14="E",C14="W",C14="H"),1,IF(C14 = "S",IF(D14="M",1,0),IF(D14 = "F",1,0))),0) -> 0 | AE14: =IFERROR(IF(OR(E14="M",E14="S"),IF(E14="M",IF(OR(C14="S",C14 = "D"),0,1),IF(OR(C14="W",C14="H"),0,1)),0),0) -> 0 | AF14: =IF(G14="",-1,IF(AND(G14<=TODAY(),ISNUMBER(DATE(YEAR(G14),MONTH(G14),DAY(G14)))),IF(AND(OR(C14="S",C14="D"),J14>24),-1,1),-1)) -> -1 | AG14: =IF(OR(I14="CAT 1",I14="CAT 2",I14="CAT 3",I14="CAT 4"),1,0) -> 0 | AH14: =PRODUCT(AF14:AG14)*AE14 -> 0 | AJ14: =AJ13+5 -> 60 | AK14: 60-64
A15: 14 | J15: =IFERROR(IF(G15="","",ROUNDDOWN(IF($G15="","",(inception_date-$G15)/365.25),0)),0) | K15: =IF(I15="","",IF($AM$3=1,IFERROR(IF(J15=FALSE,"",VLOOKUP(J15,$AJ$1:$AK$18,2,1)),""),IFERROR(IF(J15 = "FALSE","",VLOOKUP(J15,#REF!,2,TRUE)),""))) | O15: =IF(C15="","",IF(R15=1,"Yes","No")) | P15: =IFERROR(IF(C15="","",IF(AND(Census!C15="E",Census!J15>=18,Census!J15<=65),"Yes","No")),"ERROR") | Q15: =IFERROR(IF(C15="","",IF(AND(Census!C15="E",Census!J15>=18,Census!J15<=64),"Yes","No")),"ERROR") | R15: =IF(OR(AB15<>1,AC15<>1,AD15<>1,AF15<>1,AE15<>1,AG15<>1),-1,1) -> -1 | S15: =AB15 -> 0 | T15: =AC15 -> 0 | U15: =AD15 -> 0 | V15: =AE15 -> 0 | W15: =AF15 -> -1 | X15: =AG15 -> 0 | AB15: =IFERROR(IF(OR(B15=0,B15=""),0,1),0) -> 0 | AC15: =IFERROR(IF(OR(C15="S",C15="D"),IF(AND(C15="D",D15="F"),1,IF(AND(C15="S",D15="M"),1,0)),IF(OR(C15="W",C15="H"),IF(OR(AND(C15="W",D15="F"),AND(C15="H",D15="M")),1,),IF(OR(D15="M",D15="F"),1,0))),0) -> 0 | AD15: =IFERROR(IF(OR(C15="E",C15="W",C15="H"),1,IF(C15 = "S",IF(D15="M",1,0),IF(D15 = "F",1,0))),0) -> 0 | AE15: =IFERROR(IF(OR(E15="M",E15="S"),IF(E15="M",IF(OR(C15="S",C15 = "D"),0,1),IF(OR(C15="W",C15="H"),0,1)),0),0) -> 0 | AF15: =IF(G15="",-1,IF(AND(G15<=TODAY(),ISNUMBER(DATE(YEAR(G15),MONTH(G15),DAY(G15)))),IF(AND(OR(C15="S",C15="D"),J15>24),-1,1),-1)) -> -1 | AG15: =IF(OR(I15="CAT 1",I15="CAT 2",I15="CAT 3",I15="CAT 4"),1,0) -> 0 | AH15: =PRODUCT(AF15:AG15)*AE15 -> 0 | AJ15: =AJ14+5 -> 65 | AK15: 65-69
A16: 15 | J16: =IFERROR(IF(G16="","",ROUNDDOWN(IF($G16="","",(inception_date-$G16)/365.25),0)),0) | K16: =IF(I16="","",IF($AM$3=1,IFERROR(IF(J16=FALSE,"",VLOOKUP(J16,$AJ$1:$AK$18,2,1)),""),IFERROR(IF(J16 = "FALSE","",VLOOKUP(J16,#REF!,2,TRUE)),""))) | O16: =IF(C16="","",IF(R16=1,"Yes","No")) | P16: =IFERROR(IF(C16="","",IF(AND(Census!C16="E",Census!J16>=18,Census!J16<=65),"Yes","No")),"ERROR") | Q16: =IFERROR(IF(C16="","",IF(AND(Census!C16="E",Census!J16>=18,Census!J16<=64),"Yes","No")),"ERROR") | R16: =IF(OR(AB16<>1,AC16<>1,AD16<>1,AF16<>1,AE16<>1,AG16<>1),-1,1) -> -1 | S16: =AB16 -> 0 | T16: =AC16 -> 0 | U16: =AD16 -> 0 | V16: =AE16 -> 0 | W16: =AF16 -> -1 | X16: =AG16 -> 0 | AB16: =IFERROR(IF(OR(B16=0,B16=""),0,1),0) -> 0 | AC16: =IFERROR(IF(OR(C16="S",C16="D"),IF(AND(C16="D",D16="F"),1,IF(AND(C16="S",D16="M"),1,0)),IF(OR(C16="W",C16="H"),IF(OR(AND(C16="W",D16="F"),AND(C16="H",D16="M")),1,),IF(OR(D16="M",D16="F"),1,0))),0) -> 0 | AD16: =IFERROR(IF(OR(C16="E",C16="W",C16="H"),1,IF(C16 = "S",IF(D16="M",1,0),IF(D16 = "F",1,0))),0) -> 0 | AE16: =IFERROR(IF(OR(E16="M",E16="S"),IF(E16="M",IF(OR(C16="S",C16 = "D"),0,1),IF(OR(C16="W",C16="H"),0,1)),0),0) -> 0 | AF16: =IF(G16="",-1,IF(AND(G16<=TODAY(),ISNUMBER(DATE(YEAR(G16),MONTH(G16),DAY(G16)))),IF(AND(OR(C16="S",C16="D"),J16>24),-1,1),-1)) -> -1 | AG16: =IF(OR(I16="CAT 1",I16="CAT 2",I16="CAT 3",I16="CAT 4"),1,0) -> 0 | AH16: =PRODUCT(AF16:AG16)*AE16 -> 0 | AJ16: =AJ15+5 -> 70 | AK16: 70-74
A17: 16 | J17: =IFERROR(IF(G17="","",ROUNDDOWN(IF($G17="","",(inception_date-$G17)/365.25),0)),0) | K17: =IF(I17="","",IF($AM$3=1,IFERROR(IF(J17=FALSE,"",VLOOKUP(J17,$AJ$1:$AK$18,2,1)),""),IFERROR(IF(J17 = "FALSE","",VLOOKUP(J17,#REF!,2,TRUE)),""))) | O17: =IF(C17="","",IF(R17=1,"Yes","No")) | P17: =IFERROR(IF(C17="","",IF(AND(Census!C17="E",Census!J17>=18,Census!J17<=65),"Yes","No")),"ERROR") | Q17: =IFERROR(IF(C17="","",IF(AND(Census!C17="E",Census!J17>=18,Census!J17<=64),"Yes","No")),"ERROR") | R17: =IF(OR(AB17<>1,AC17<>1,AD17<>1,AF17<>1,AE17<>1,AG17<>1),-1,1) -> -1 | S17: =AB17 -> 0 | T17: =AC17 -> 0 | U17: =AD17 -> 0 | V17: =AE17 -> 0 | W17: =AF17 -> -1 | X17: =AG17 -> 0 | AB17: =IFERROR(IF(OR(B17=0,B17=""),0,1),0) -> 0 | AC17: =IFERROR(IF(OR(C17="S",C17="D"),IF(AND(C17="D",D17="F"),1,IF(AND(C17="S",D17="M"),1,0)),IF(OR(C17="W",C17="H"),IF(OR(AND(C17="W",D17="F"),AND(C17="H",D17="M")),1,),IF(OR(D17="M",D17="F"),1,0))),0) -> 0 | AD17: =IFERROR(IF(OR(C17="E",C17="W",C17="H"),1,IF(C17 = "S",IF(D17="M",1,0),IF(D17 = "F",1,0))),0) -> 0 | AE17: =IFERROR(IF(OR(E17="M",E17="S"),IF(E17="M",IF(OR(C17="S",C17 = "D"),0,1),IF(OR(C17="W",C17="H"),0,1)),0),0) -> 0 | AF17: =IF(G17="",-1,IF(AND(G17<=TODAY(),ISNUMBER(DATE(YEAR(G17),MONTH(G17),DAY(G17)))),IF(AND(OR(C17="S",C17="D"),J17>24),-1,1),-1)) -> -1 | AG17: =IF(OR(I17="CAT 1",I17="CAT 2",I17="CAT 3",I17="CAT 4"),1,0) -> 0 | AH17: =PRODUCT(AF17:AG17)*AE17 -> 0 | AJ17: =AJ16+5 -> 75 | AK17: 75-79
A18: 17 | J18: =IFERROR(IF(G18="","",ROUNDDOWN(IF($G18="","",(inception_date-$G18)/365.25),0)),0) | K18: =IF(I18="","",IF($AM$3=1,IFERROR(IF(J18=FALSE,"",VLOOKUP(J18,$AJ$1:$AK$18,2,1)),""),IFERROR(IF(J18 = "FALSE","",VLOOKUP(J18,#REF!,2,TRUE)),""))) | O18: =IF(C18="","",IF(R18=1,"Yes","No")) | P18: =IFERROR(IF(C18="","",IF(AND(Census!C18="E",Census!J18>=18,Census!J18<=65),"Yes","No")),"ERROR") | Q18: =IFERROR(IF(C18="","",IF(AND(Census!C18="E",Census!J18>=18,Census!J18<=64),"Yes","No")),"ERROR") | R18: =IF(OR(AB18<>1,AC18<>1,AD18<>1,AF18<>1,AE18<>1,AG18<>1),-1,1) -> -1 | S18: =AB18 -> 0 | T18: =AC18 -> 0 | U18: =AD18 -> 0 | V18: =AE18 -> 0 | W18: =AF18 -> -1 | X18: =AG18 -> 0 | AB18: =IFERROR(IF(OR(B18=0,B18=""),0,1),0) -> 0 | AC18: =IFERROR(IF(OR(C18="S",C18="D"),IF(AND(C18="D",D18="F"),1,IF(AND(C18="S",D18="M"),1,0)),IF(OR(C18="W",C18="H"),IF(OR(AND(C18="W",D18="F"),AND(C18="H",D18="M")),1,),IF(OR(D18="M",D18="F"),1,0))),0) -> 0 | AD18: =IFERROR(IF(OR(C18="E",C18="W",C18="H"),1,IF(C18 = "S",IF(D18="M",1,0),IF(D18 = "F",1,0))),0) -> 0 | AE18: =IFERROR(IF(OR(E18="M",E18="S"),IF(E18="M",IF(OR(C18="S",C18 = "D"),0,1),IF(OR(C18="W",C18="H"),0,1)),0),0) -> 0 | AF18: =IF(G18="",-1,IF(AND(G18<=TODAY(),ISNUMBER(DATE(YEAR(G18),MONTH(G18),DAY(G18)))),IF(AND(OR(C18="S",C18="D"),J18>24),-1,1),-1)) -> -1 | AG18: =IF(OR(I18="CAT 1",I18="CAT 2",I18="CAT 3",I18="CAT 4"),1,0) -> 0 | AH18: =PRODUCT(AF18:AG18)*AE18 -> 0 | AJ18: =AJ17+5 -> 80 | AK18: 80-Above
A19: 18 | J19: =IFERROR(IF(G19="","",ROUNDDOWN(IF($G19="","",(inception_date-$G19)/365.25),0)),0) | K19: =IF(I19="","",IF($AM$3=1,IFERROR(IF(J19=FALSE,"",VLOOKUP(J19,$AJ$1:$AK$18,2,1)),""),IFERROR(IF(J19 = "FALSE","",VLOOKUP(J19,#REF!,2,TRUE)),""))) | O19: =IF(C19="","",IF(R19=1,"Yes","No")) | P19: =IFERROR(IF(C19="","",IF(AND(Census!C19="E",Census!J19>=18,Census!J19<=65),"Yes","No")),"ERROR") | Q19: =IFERROR(IF(C19="","",IF(AND(Census!C19="E",Census!J19>=18,Census!J19<=64),"Yes","No")),"ERROR") | R19: =IF(OR(AB19<>1,AC19<>1,AD19<>1,AF19<>1,AE19<>1,AG19<>1),-1,1) -> -1 | S19: =AB19 -> 0 | T19: =AC19 -> 0 | U19: =AD19 -> 0 | V19: =AE19 -> 0 | W19: =AF19 -> -1 | X19: =AG19 -> 0 | AB19: =IFERROR(IF(OR(B19=0,B19=""),0,1),0) -> 0 | AC19: =IFERROR(IF(OR(C19="S",C19="D"),IF(AND(C19="D",D19="F"),1,IF(AND(C19="S",D19="M"),1,0)),IF(OR(C19="W",C19="H"),IF(OR(AND(C19="W",D19="F"),AND(C19="H",D19="M")),1,),IF(OR(D19="M",D19="F"),1,0))),0) -> 0 | AD19: =IFERROR(IF(OR(C19="E",C19="W",C19="H"),1,IF(C19 = "S",IF(D19="M",1,0),IF(D19 = "F",1,0))),0) -> 0 | AE19: =IFERROR(IF(OR(E19="M",E19="S"),IF(E19="M",IF(OR(C19="S",C19 = "D"),0,1),IF(OR(C19="W",C19="H"),0,1)),0),0) -> 0 | AF19: =IF(G19="",-1,IF(AND(G19<=TODAY(),ISNUMBER(DATE(YEAR(G19),MONTH(G19),DAY(G19)))),IF(AND(OR(C19="S",C19="D"),J19>24),-1,1),-1)) -> -1 | AG19: =IF(OR(I19="CAT 1",I19="CAT 2",I19="CAT 3",I19="CAT 4"),1,0) -> 0 | AH19: =PRODUCT(AF19:AG19)*AE19 -> 0
A20: 19 | J20: =IFERROR(IF(G20="","",ROUNDDOWN(IF($G20="","",(inception_date-$G20)/365.25),0)),0) | K20: =IF(I20="","",IF($AM$3=1,IFERROR(IF(J20=FALSE,"",VLOOKUP(J20,$AJ$1:$AK$18,2,1)),""),IFERROR(IF(J20 = "FALSE","",VLOOKUP(J20,#REF!,2,TRUE)),""))) | O20: =IF(C20="","",IF(R20=1,"Yes","No")) | P20: =IFERROR(IF(C20="","",IF(AND(Census!C20="E",Census!J20>=18,Census!J20<=65),"Yes","No")),"ERROR") | Q20: =IFERROR(IF(C20="","",IF(AND(Census!C20="E",Census!J20>=18,Census!J20<=64),"Yes","No")),"ERROR") | R20: =IF(OR(AB20<>1,AC20<>1,AD20<>1,AF20<>1,AE20<>1,AG20<>1),-1,1) -> -1 | S20: =AB20 -> 0 | T20: =AC20 -> 0 | U20: =AD20 -> 0 | V20: =AE20 -> 0 | W20: =AF20 -> -1 | X20: =AG20 -> 0 | AB20: =IFERROR(IF(OR(B20=0,B20=""),0,1),0) -> 0 | AC20: =IFERROR(IF(OR(C20="S",C20="D"),IF(AND(C20="D",D20="F"),1,IF(AND(C20="S",D20="M"),1,0)),IF(OR(C20="W",C20="H"),IF(OR(AND(C20="W",D20="F"),AND(C20="H",D20="M")),1,),IF(OR(D20="M",D20="F"),1,0))),0) -> 0 | AD20: =IFERROR(IF(OR(C20="E",C20="W",C20="H"),1,IF(C20 = "S",IF(D20="M",1,0),IF(D20 = "F",1,0))),0) -> 0 | AE20: =IFERROR(IF(OR(E20="M",E20="S"),IF(E20="M",IF(OR(C20="S",C20 = "D"),0,1),IF(OR(C20="W",C20="H"),0,1)),0),0) -> 0 | AF20: =IF(G20="",-1,IF(AND(G20<=TODAY(),ISNUMBER(DATE(YEAR(G20),MONTH(G20),DAY(G20)))),IF(AND(OR(C20="S",C20="D"),J20>24),-1,1),-1)) -> -1 | AG20: =IF(OR(I20="CAT 1",I20="CAT 2",I20="CAT 3",I20="CAT 4"),1,0) -> 0 | AH20: =PRODUCT(AF20:AG20)*AE20 -> 0
A21: 20 | J21: =IFERROR(IF(G21="","",ROUNDDOWN(IF($G21="","",(inception_date-$G21)/365.25),0)),0) | K21: =IF(I21="","",IF($AM$3=1,IFERROR(IF(J21=FALSE,"",VLOOKUP(J21,$AJ$1:$AK$18,2,1)),""),IFERROR(IF(J21 = "FALSE","",VLOOKUP(J21,#REF!,2,TRUE)),""))) | O21: =IF(C21="","",IF(R21=1,"Yes","No")) | P21: =IFERROR(IF(C21="","",IF(AND(Census!C21="E",Census!J21>=18,Census!J21<=65),"Yes","No")),"ERROR") | Q21: =IFERROR(IF(C21="","",IF(AND(Census!C21="E",Census!J21>=18,Census!J21<=64),"Yes","No")),"ERROR") | R21: =IF(OR(AB21<>1,AC21<>1,AD21<>1,AF21<>1,AE21<>1,AG21<>1),-1,1) -> -1 | S21: =AB21 -> 0 | T21: =AC21 -> 0 | U21: =AD21 -> 0 | V21: =AE21 -> 0 | W21: =AF21 -> -1 | X21: =AG21 -> 0 | AB21: =IFERROR(IF(OR(B21=0,B21=""),0,1),0) -> 0 | AC21: =IFERROR(IF(OR(C21="S",C21="D"),IF(AND(C21="D",D21="F"),1,IF(AND(C21="S",D21="M"),1,0)),IF(OR(C21="W",C21="H"),IF(OR(AND(C21="W",D21="F"),AND(C21="H",D21="M")),1,),IF(OR(D21="M",D21="F"),1,0))),0) -> 0 | AD21: =IFERROR(IF(OR(C21="E",C21="W",C21="H"),1,IF(C21 = "S",IF(D21="M",1,0),IF(D21 = "F",1,0))),0) -> 0 | AE21: =IFERROR(IF(OR(E21="M",E21="S"),IF(E21="M",IF(OR(C21="S",C21 = "D"),0,1),IF(OR(C21="W",C21="H"),0,1)),0),0) -> 0 | AF21: =IF(G21="",-1,IF(AND(G21<=TODAY(),ISNUMBER(DATE(YEAR(G21),MONTH(G21),DAY(G21)))),IF(AND(OR(C21="S",C21="D"),J21>24),-1,1),-1)) -> -1 | AG21: =IF(OR(I21="CAT 1",I21="CAT 2",I21="CAT 3",I21="CAT 4"),1,0) -> 0 | AH21: =PRODUCT(AF21:AG21)*AE21 -> 0 | AJ21: nb non vide Age
A22: 21 | J22: =IFERROR(IF(G22="","",ROUNDDOWN(IF($G22="","",(inception_date-$G22)/365.25),0)),0) | K22: =IF(I22="","",IF($AM$3=1,IFERROR(IF(J22=FALSE,"",VLOOKUP(J22,$AJ$1:$AK$18,2,1)),""),IFERROR(IF(J22 = "FALSE","",VLOOKUP(J22,#REF!,2,TRUE)),""))) | O22: =IF(C22="","",IF(R22=1,"Yes","No")) | P22: =IFERROR(IF(C22="","",IF(AND(Census!C22="E",Census!J22>=18,Census!J22<=65),"Yes","No")),"ERROR") | Q22: =IFERROR(IF(C22="","",IF(AND(Census!C22="E",Census!J22>=18,Census!J22<=64),"Yes","No")),"ERROR") | R22: =IF(OR(AB22<>1,AC22<>1,AD22<>1,AF22<>1,AE22<>1,AG22<>1),-1,1) -> -1 | S22: =AB22 -> 0 | T22: =AC22 -> 0 | U22: =AD22 -> 0 | V22: =AE22 -> 0 | W22: =AF22 -> -1 | X22: =AG22 -> 0 | AB22: =IFERROR(IF(OR(B22=0,B22=""),0,1),0) -> 0 | AC22: =IFERROR(IF(OR(C22="S",C22="D"),IF(AND(C22="D",D22="F"),1,IF(AND(C22="S",D22="M"),1,0)),IF(OR(C22="W",C22="H"),IF(OR(AND(C22="W",D22="F"),AND(C22="H",D22="M")),1,),IF(OR(D22="M",D22="F"),1,0))),0) -> 0 | AD22: =IFERROR(IF(OR(C22="E",C22="W",C22="H"),1,IF(C22 = "S",IF(D22="M",1,0),IF(D22 = "F",1,0))),0) -> 0 | AE22: =IFERROR(IF(OR(E22="M",E22="S"),IF(E22="M",IF(OR(C22="S",C22 = "D"),0,1),IF(OR(C22="W",C22="H"),0,1)),0),0) -> 0 | AF22: =IF(G22="",-1,IF(AND(G22<=TODAY(),ISNUMBER(DATE(YEAR(G22),MONTH(G22),DAY(G22)))),IF(AND(OR(C22="S",C22="D"),J22>24),-1,1),-1)) -> -1 | AG22: =IF(OR(I22="CAT 1",I22="CAT 2",I22="CAT 3",I22="CAT 4"),1,0) -> 0 | AH22: =PRODUCT(AF22:AG22)*AE22 -> 0 | AJ22: nb non vide Categ
A23: 22 | J23: =IFERROR(IF(G23="","",ROUNDDOWN(IF($G23="","",(inception_date-$G23)/365.25),0)),0) | K23: =IF(I23="","",IF($AM$3=1,IFERROR(IF(J23=FALSE,"",VLOOKUP(J23,$AJ$1:$AK$18,2,1)),""),IFERROR(IF(J23 = "FALSE","",VLOOKUP(J23,#REF!,2,TRUE)),""))) | O23: =IF(C23="","",IF(R23=1,"Yes","No")) | P23: =IFERROR(IF(C23="","",IF(AND(Census!C23="E",Census!J23>=18,Census!J23<=65),"Yes","No")),"ERROR") | Q23: =IFERROR(IF(C23="","",IF(AND(Census!C23="E",Census!J23>=18,Census!J23<=64),"Yes","No")),"ERROR") | R23: =IF(OR(AB23<>1,AC23<>1,AD23<>1,AF23<>1,AE23<>1,AG23<>1),-1,1) -> -1 | S23: =AB23 -> 0 | T23: =AC23 -> 0 | U23: =AD23 -> 0 | V23: =AE23 -> 0 | W23: =AF23 -> -1 | X23: =AG23 -> 0 | AB23: =IFERROR(IF(OR(B23=0,B23=""),0,1),0) -> 0 | AC23: =IFERROR(IF(OR(C23="S",C23="D"),IF(AND(C23="D",D23="F"),1,IF(AND(C23="S",D23="M"),1,0)),IF(OR(C23="W",C23="H"),IF(OR(AND(C23="W",D23="F"),AND(C23="H",D23="M")),1,),IF(OR(D23="M",D23="F"),1,0))),0) -> 0 | AD23: =IFERROR(IF(OR(C23="E",C23="W",C23="H"),1,IF(C23 = "S",IF(D23="M",1,0),IF(D23 = "F",1,0))),0) -> 0 | AE23: =IFERROR(IF(OR(E23="M",E23="S"),IF(E23="M",IF(OR(C23="S",C23 = "D"),0,1),IF(OR(C23="W",C23="H"),0,1)),0),0) -> 0 | AF23: =IF(G23="",-1,IF(AND(G23<=TODAY(),ISNUMBER(DATE(YEAR(G23),MONTH(G23),DAY(G23)))),IF(AND(OR(C23="S",C23="D"),J23>24),-1,1),-1)) -> -1 | AG23: =IF(OR(I23="CAT 1",I23="CAT 2",I23="CAT 3",I23="CAT 4"),1,0) -> 0 | AH23: =PRODUCT(AF23:AG23)*AE23 -> 0 | AJ23: nb non vide Age
A24: 23 | J24: =IFERROR(IF(G24="","",ROUNDDOWN(IF($G24="","",(inception_date-$G24)/365.25),0)),0) | K24: =IF(I24="","",IF($AM$3=1,IFERROR(IF(J24=FALSE,"",VLOOKUP(J24,$AJ$1:$AK$18,2,1)),""),IFERROR(IF(J24 = "FALSE","",VLOOKUP(J24,#REF!,2,TRUE)),""))) | O24: =IF(C24="","",IF(R24=1,"Yes","No")) | P24: =IFERROR(IF(C24="","",IF(AND(Census!C24="E",Census!J24>=18,Census!J24<=65),"Yes","No")),"ERROR") | Q24: =IFERROR(IF(C24="","",IF(AND(Census!C24="E",Census!J24>=18,Census!J24<=64),"Yes","No")),"ERROR") | R24: =IF(OR(AB24<>1,AC24<>1,AD24<>1,AF24<>1,AE24<>1,AG24<>1),-1,1) -> -1 | S24: =AB24 -> 0 | T24: =AC24 -> 0 | U24: =AD24 -> 0 | V24: =AE24 -> 0 | W24: =AF24 -> -1 | X24: =AG24 -> 0 | AB24: =IFERROR(IF(OR(B24=0,B24=""),0,1),0) -> 0 | AC24: =IFERROR(IF(OR(C24="S",C24="D"),IF(AND(C24="D",D24="F"),1,IF(AND(C24="S",D24="M"),1,0)),IF(OR(C24="W",C24="H"),IF(OR(AND(C24="W",D24="F"),AND(C24="H",D24="M")),1,),IF(OR(D24="M",D24="F"),1,0))),0) -> 0 | AD24: =IFERROR(IF(OR(C24="E",C24="W",C24="H"),1,IF(C24 = "S",IF(D24="M",1,0),IF(D24 = "F",1,0))),0) -> 0 | AE24: =IFERROR(IF(OR(E24="M",E24="S"),IF(E24="M",IF(OR(C24="S",C24 = "D"),0,1),IF(OR(C24="W",C24="H"),0,1)),0),0) -> 0 | AF24: =IF(G24="",-1,IF(AND(G24<=TODAY(),ISNUMBER(DATE(YEAR(G24),MONTH(G24),DAY(G24)))),IF(AND(OR(C24="S",C24="D"),J24>24),-1,1),-1)) -> -1 | AG24: =IF(OR(I24="CAT 1",I24="CAT 2",I24="CAT 3",I24="CAT 4"),1,0) -> 0 | AH24: =PRODUCT(AF24:AG24)*AE24 -> 0
A25: 24 | J25: =IFERROR(IF(G25="","",ROUNDDOWN(IF($G25="","",(inception_date-$G25)/365.25),0)),0) | K25: =IF(I25="","",IF($AM$3=1,IFERROR(IF(J25=FALSE,"",VLOOKUP(J25,$AJ$1:$AK$18,2,1)),""),IFERROR(IF(J25 = "FALSE","",VLOOKUP(J25,#REF!,2,TRUE)),""))) | O25: =IF(C25="","",IF(R25=1,"Yes","No")) | P25: =IFERROR(IF(C25="","",IF(AND(Census!C25="E",Census!J25>=18,Census!J25<=65),"Yes","No")),"ERROR") | Q25: =IFERROR(IF(C25="","",IF(AND(Census!C25="E",Census!J25>=18,Census!J25<=64),"Yes","No")),"ERROR") | R25: =IF(OR(AB25<>1,AC25<>1,AD25<>1,AF25<>1,AE25<>1,AG25<>1),-1,1) -> -1 | S25: =AB25 -> 0 | T25: =AC25 -> 0 | U25: =AD25 -> 0 | V25: =AE25 -> 0 | W25: =AF25 -> -1 | X25: =AG25 -> 0 | AB25: =IFERROR(IF(OR(B25=0,B25=""),0,1),0) -> 0 | AC25: =IFERROR(IF(OR(C25="S",C25="D"),IF(AND(C25="D",D25="F"),1,IF(AND(C25="S",D25="M"),1,0)),IF(OR(C25="W",C25="H"),IF(OR(AND(C25="W",D25="F"),AND(C25="H",D25="M")),1,),IF(OR(D25="M",D25="F"),1,0))),0) -> 0 | AD25: =IFERROR(IF(OR(C25="E",C25="W",C25="H"),1,IF(C25 = "S",IF(D25="M",1,0),IF(D25 = "F",1,0))),0) -> 0 | AE25: =IFERROR(IF(OR(E25="M",E25="S"),IF(E25="M",IF(OR(C25="S",C25 = "D"),0,1),IF(OR(C25="W",C25="H"),0,1)),0),0) -> 0 | AF25: =IF(G25="",-1,IF(AND(G25<=TODAY(),ISNUMBER(DATE(YEAR(G25),MONTH(G25),DAY(G25)))),IF(AND(OR(C25="S",C25="D"),J25>24),-1,1),-1)) -> -1 | AG25: =IF(OR(I25="CAT 1",I25="CAT 2",I25="CAT 3",I25="CAT 4"),1,0) -> 0 | AH25: =PRODUCT(AF25:AG25)*AE25 -> 0
A26: 25 | J26: =IFERROR(IF(G26="","",ROUNDDOWN(IF($G26="","",(inception_date-$G26)/365.25),0)),0) | K26: =IF(I26="","",IF($AM$3=1,IFERROR(IF(J26=FALSE,"",VLOOKUP(J26,$AJ$1:$AK$18,2,1)),""),IFERROR(IF(J26 = "FALSE","",VLOOKUP(J26,#REF!,2,TRUE)),""))) | O26: =IF(C26="","",IF(R26=1,"Yes","No")) | P26: =IFERROR(IF(C26="","",IF(AND(Census!C26="E",Census!J26>=18,Census!J26<=65),"Yes","No")),"ERROR") | Q26: =IFERROR(IF(C26="","",IF(AND(Census!C26="E",Census!J26>=18,Census!J26<=64),"Yes","No")),"ERROR") | R26: =IF(OR(AB26<>1,AC26<>1,AD26<>1,AF26<>1,AE26<>1,AG26<>1),-1,1) -> -1 | S26: =AB26 -> 0 | T26: =AC26 -> 0 | U26: =AD26 -> 0 | V26: =AE26 -> 0 | W26: =AF26 -> -1 | X26: =AG26 -> 0 | AB26: =IFERROR(IF(OR(B26=0,B26=""),0,1),0) -> 0 | AC26: =IFERROR(IF(OR(C26="S",C26="D"),IF(AND(C26="D",D26="F"),1,IF(AND(C26="S",D26="M"),1,0)),IF(OR(C26="W",C26="H"),IF(OR(AND(C26="W",D26="F"),AND(C26="H",D26="M")),1,),IF(OR(D26="M",D26="F"),1,0))),0) -> 0 | AD26: =IFERROR(IF(OR(C26="E",C26="W",C26="H"),1,IF(C26 = "S",IF(D26="M",1,0),IF(D26 = "F",1,0))),0) -> 0 | AE26: =IFERROR(IF(OR(E26="M",E26="S"),IF(E26="M",IF(OR(C26="S",C26 = "D"),0,1),IF(OR(C26="W",C26="H"),0,1)),0),0) -> 0 | AF26: =IF(G26="",-1,IF(AND(G26<=TODAY(),ISNUMBER(DATE(YEAR(G26),MONTH(G26),DAY(G26)))),IF(AND(OR(C26="S",C26="D"),J26>24),-1,1),-1)) -> -1 | AG26: =IF(OR(I26="CAT 1",I26="CAT 2",I26="CAT 3",I26="CAT 4"),1,0) -> 0 | AH26: =PRODUCT(AF26:AG26)*AE26 -> 0
A27: 26 | J27: =IFERROR(IF(G27="","",ROUNDDOWN(IF($G27="","",(inception_date-$G27)/365.25),0)),0) | K27: =IF(I27="","",IF($AM$3=1,IFERROR(IF(J27=FALSE,"",VLOOKUP(J27,$AJ$1:$AK$18,2,1)),""),IFERROR(IF(J27 = "FALSE","",VLOOKUP(J27,#REF!,2,TRUE)),""))) | O27: =IF(C27="","",IF(R27=1,"Yes","No")) | P27: =IFERROR(IF(C27="","",IF(AND(Census!C27="E",Census!J27>=18,Census!J27<=65),"Yes","No")),"ERROR") | Q27: =IFERROR(IF(C27="","",IF(AND(Census!C27="E",Census!J27>=18,Census!J27<=64),"Yes","No")),"ERROR") | R27: =IF(OR(AB27<>1,AC27<>1,AD27<>1,AF27<>1,AE27<>1,AG27<>1),-1,1) -> -1 | S27: =AB27 -> 0 | T27: =AC27 -> 0 | U27: =AD27 -> 0 | V27: =AE27 -> 0 | W27: =AF27 -> -1 | X27: =AG27 -> 0 | AB27: =IFERROR(IF(OR(B27=0,B27=""),0,1),0) -> 0 | AC27: =IFERROR(IF(OR(C27="S",C27="D"),IF(AND(C27="D",D27="F"),1,IF(AND(C27="S",D27="M"),1,0)),IF(OR(C27="W",C27="H"),IF(OR(AND(C27="W",D27="F"),AND(C27="H",D27="M")),1,),IF(OR(D27="M",D27="F"),1,0))),0) -> 0 | AD27: =IFERROR(IF(OR(C27="E",C27="W",C27="H"),1,IF(C27 = "S",IF(D27="M",1,0),IF(D27 = "F",1,0))),0) -> 0 | AE27: =IFERROR(IF(OR(E27="M",E27="S"),IF(E27="M",IF(OR(C27="S",C27 = "D"),0,1),IF(OR(C27="W",C27="H"),0,1)),0),0) -> 0 | AF27: =IF(G27="",-1,IF(AND(G27<=TODAY(),ISNUMBER(DATE(YEAR(G27),MONTH(G27),DAY(G27)))),IF(AND(OR(C27="S",C27="D"),J27>24),-1,1),-1)) -> -1 | AG27: =IF(OR(I27="CAT 1",I27="CAT 2",I27="CAT 3",I27="CAT 4"),1,0) -> 0 | AH27: =PRODUCT(AF27:AG27)*AE27 -> 0
A28: 27 | J28: =IFERROR(IF(G28="","",ROUNDDOWN(IF($G28="","",(inception_date-$G28)/365.25),0)),0) | K28: =IF(I28="","",IF($AM$3=1,IFERROR(IF(J28=FALSE,"",VLOOKUP(J28,$AJ$1:$AK$18,2,1)),""),IFERROR(IF(J28 = "FALSE","",VLOOKUP(J28,#REF!,2,TRUE)),""))) | O28: =IF(C28="","",IF(R28=1,"Yes","No")) | P28: =IFERROR(IF(C28="","",IF(AND(Census!C28="E",Census!J28>=18,Census!J28<=65),"Yes","No")),"ERROR") | Q28: =IFERROR(IF(C28="","",IF(AND(Census!C28="E",Census!J28>=18,Census!J28<=64),"Yes","No")),"ERROR") | R28: =IF(OR(AB28<>1,AC28<>1,AD28<>1,AF28<>1,AE28<>1,AG28<>1),-1,1) -> -1 | S28: =AB28 -> 0 | T28: =AC28 -> 0 | U28: =AD28 -> 0 | V28: =AE28 -> 0 | W28: =AF28 -> -1 | X28: =AG28 -> 0 | AB28: =IFERROR(IF(OR(B28=0,B28=""),0,1),0) -> 0 | AC28: =IFERROR(IF(OR(C28="S",C28="D"),IF(AND(C28="D",D28="F"),1,IF(AND(C28="S",D28="M"),1,0)),IF(OR(C28="W",C28="H"),IF(OR(AND(C28="W",D28="F"),AND(C28="H",D28="M")),1,),IF(OR(D28="M",D28="F"),1,0))),0) -> 0 | AD28: =IFERROR(IF(OR(C28="E",C28="W",C28="H"),1,IF(C28 = "S",IF(D28="M",1,0),IF(D28 = "F",1,0))),0) -> 0 | AE28: =IFERROR(IF(OR(E28="M",E28="S"),IF(E28="M",IF(OR(C28="S",C28 = "D"),0,1),IF(OR(C28="W",C28="H"),0,1)),0),0) -> 0 | AF28: =IF(G28="",-1,IF(AND(G28<=TODAY(),ISNUMBER(DATE(YEAR(G28),MONTH(G28),DAY(G28)))),IF(AND(OR(C28="S",C28="D"),J28>24),-1,1),-1)) -> -1 | AG28: =IF(OR(I28="CAT 1",I28="CAT 2",I28="CAT 3",I28="CAT 4"),1,0) -> 0 | AH28: =PRODUCT(AF28:AG28)*AE28 -> 0
A29: 28 | J29: =IFERROR(IF(G29="","",ROUNDDOWN(IF($G29="","",(inception_date-$G29)/365.25),0)),0) | K29: =IF(I29="","",IF($AM$3=1,IFERROR(IF(J29=FALSE,"",VLOOKUP(J29,$AJ$1:$AK$18,2,1)),""),IFERROR(IF(J29 = "FALSE","",VLOOKUP(J29,#REF!,2,TRUE)),""))) | O29: =IF(C29="","",IF(R29=1,"Yes","No")) | P29: =IFERROR(IF(C29="","",IF(AND(Census!C29="E",Census!J29>=18,Census!J29<=65),"Yes","No")),"ERROR") | Q29: =IFERROR(IF(C29="","",IF(AND(Census!C29="E",Census!J29>=18,Census!J29<=64),"Yes","No")),"ERROR") | R29: =IF(OR(AB29<>1,AC29<>1,AD29<>1,AF29<>1,AE29<>1,AG29<>1),-1,1) -> -1 | S29: =AB29 -> 0 | T29: =AC29 -> 0 | U29: =AD29 -> 0 | V29: =AE29 -> 0 | W29: =AF29 -> -1 | X29: =AG29 -> 0 | AB29: =IFERROR(IF(OR(B29=0,B29=""),0,1),0) -> 0 | AC29: =IFERROR(IF(OR(C29="S",C29="D"),IF(AND(C29="D",D29="F"),1,IF(AND(C29="S",D29="M"),1,0)),IF(OR(C29="W",C29="H"),IF(OR(AND(C29="W",D29="F"),AND(C29="H",D29="M")),1,),IF(OR(D29="M",D29="F"),1,0))),0) -> 0 | AD29: =IFERROR(IF(OR(C29="E",C29="W",C29="H"),1,IF(C29 = "S",IF(D29="M",1,0),IF(D29 = "F",1,0))),0) -> 0 | AE29: =IFERROR(IF(OR(E29="M",E29="S"),IF(E29="M",IF(OR(C29="S",C29 = "D"),0,1),IF(OR(C29="W",C29="H"),0,1)),0),0) -> 0 | AF29: =IF(G29="",-1,IF(AND(G29<=TODAY(),ISNUMBER(DATE(YEAR(G29),MONTH(G29),DAY(G29)))),IF(AND(OR(C29="S",C29="D"),J29>24),-1,1),-1)) -> -1 | AG29: =IF(OR(I29="CAT 1",I29="CAT 2",I29="CAT 3",I29="CAT 4"),1,0) -> 0 | AH29: =PRODUCT(AF29:AG29)*AE29 -> 0
A30: 29 | J30: =IFERROR(IF(G30="","",ROUNDDOWN(IF($G30="","",(inception_date-$G30)/365.25),0)),0) | K30: =IF(I30="","",IF($AM$3=1,IFERROR(IF(J30=FALSE,"",VLOOKUP(J30,$AJ$1:$AK$18,2,1)),""),IFERROR(IF(J30 = "FALSE","",VLOOKUP(J30,#REF!,2,TRUE)),""))) | O30: =IF(C30="","",IF(R30=1,"Yes","No")) | P30: =IFERROR(IF(C30="","",IF(AND(Census!C30="E",Census!J30>=18,Census!J30<=65),"Yes","No")),"ERROR") | Q30: =IFERROR(IF(C30="","",IF(AND(Census!C30="E",Census!J30>=18,Census!J30<=64),"Yes","No")),"ERROR") | R30: =IF(OR(AB30<>1,AC30<>1,AD30<>1,AF30<>1,AE30<>1,AG30<>1),-1,1) -> -1 | S30: =AB30 -> 0 | T30: =AC30 -> 0 | U30: =AD30 -> 0 | V30: =AE30 -> 0 | W30: =AF30 -> -1 | X30: =AG30 -> 0 | AB30: =IFERROR(IF(OR(B30=0,B30=""),0,1),0) -> 0 | AC30: =IFERROR(IF(OR(C30="S",C30="D"),IF(AND(C30="D",D30="F"),1,IF(AND(C30="S",D30="M"),1,0)),IF(OR(C30="W",C30="H"),IF(OR(AND(C30="W",D30="F"),AND(C30="H",D30="M")),1,),IF(OR(D30="M",D30="F"),1,0))),0) -> 0 | AD30: =IFERROR(IF(OR(C30="E",C30="W",C30="H"),1,IF(C30 = "S",IF(D30="M",1,0),IF(D30 = "F",1,0))),0) -> 0 | AE30: =IFERROR(IF(OR(E30="M",E30="S"),IF(E30="M",IF(OR(C30="S",C30 = "D"),0,1),IF(OR(C30="W",C30="H"),0,1)),0),0) -> 0 | AF30: =IF(G30="",-1,IF(AND(G30<=TODAY(),ISNUMBER(DATE(YEAR(G30),MONTH(G30),DAY(G30)))),IF(AND(OR(C30="S",C30="D"),J30>24),-1,1),-1)) -> -1 | AG30: =IF(OR(I30="CAT 1",I30="CAT 2",I30="CAT 3",I30="CAT 4"),1,0) -> 0 | AH30: =PRODUCT(AF30:AG30)*AE30 -> 0
A31: 30 | J31: =IFERROR(IF(G31="","",ROUNDDOWN(IF($G31="","",(inception_date-$G31)/365.25),0)),0) | K31: =IF(I31="","",IF($AM$3=1,IFERROR(IF(J31=FALSE,"",VLOOKUP(J31,$AJ$1:$AK$18,2,1)),""),IFERROR(IF(J31 = "FALSE","",VLOOKUP(J31,#REF!,2,TRUE)),""))) | O31: =IF(C31="","",IF(R31=1,"Yes","No")) | P31: =IFERROR(IF(C31="","",IF(AND(Census!C31="E",Census!J31>=18,Census!J31<=65),"Yes","No")),"ERROR") | Q31: =IFERROR(IF(C31="","",IF(AND(Census!C31="E",Census!J31>=18,Census!J31<=64),"Yes","No")),"ERROR") | R31: =IF(OR(AB31<>1,AC31<>1,AD31<>1,AF31<>1,AE31<>1,AG31<>1),-1,1) -> -1 | S31: =AB31 -> 0 | T31: =AC31 -> 0 | U31: =AD31 -> 0 | V31: =AE31 -> 0 | W31: =AF31 -> -1 | X31: =AG31 -> 0 | Z31: Afghan | AB31: =IFERROR(IF(OR(B31=0,B31=""),0,1),0) -> 0 | AC31: =IFERROR(IF(OR(C31="S",C31="D"),IF(AND(C31="D",D31="F"),1,IF(AND(C31="S",D31="M"),1,0)),IF(OR(C31="W",C31="H"),IF(OR(AND(C31="W",D31="F"),AND(C31="H",D31="M")),1,),IF(OR(D31="M",D31="F"),1,0))),0) -> 0 | AD31: =IFERROR(IF(OR(C31="E",C31="W",C31="H"),1,IF(C31 = "S",IF(D31="M",1,0),IF(D31 = "F",1,0))),0) -> 0 | AE31: =IFERROR(IF(OR(E31="M",E31="S"),IF(E31="M",IF(OR(C31="S",C31 = "D"),0,1),IF(OR(C31="W",C31="H"),0,1)),0),0) -> 0 | AF31: =IF(G31="",-1,IF(AND(G31<=TODAY(),ISNUMBER(DATE(YEAR(G31),MONTH(G31),DAY(G31)))),IF(AND(OR(C31="S",C31="D"),J31>24),-1,1),-1)) -> -1 | AG31: =IF(OR(I31="CAT 1",I31="CAT 2",I31="CAT 3",I31="CAT 4"),1,0) -> 0 | AH31: =PRODUCT(AF31:AG31)*AE31 -> 0
A32: 31 | J32: =IFERROR(IF(G32="","",ROUNDDOWN(IF($G32="","",(inception_date-$G32)/365.25),0)),0) | K32: =IF(I32="","",IF($AM$3=1,IFERROR(IF(J32=FALSE,"",VLOOKUP(J32,$AJ$1:$AK$18,2,1)),""),IFERROR(IF(J32 = "FALSE","",VLOOKUP(J32,#REF!,2,TRUE)),""))) | O32: =IF(C32="","",IF(R32=1,"Yes","No")) | P32: =IFERROR(IF(C32="","",IF(AND(Census!C32="E",Census!J32>=18,Census!J32<=65),"Yes","No")),"ERROR") | Q32: =IFERROR(IF(C32="","",IF(AND(Census!C32="E",Census!J32>=18,Census!J32<=64),"Yes","No")),"ERROR") | R32: =IF(OR(AB32<>1,AC32<>1,AD32<>1,AF32<>1,AE32<>1,AG32<>1),-1,1) -> -1 | S32: =AB32 -> 0 | T32: =AC32 -> 0 | U32: =AD32 -> 0 | V32: =AE32 -> 0 | W32: =AF32 -> -1 | X32: =AG32 -> 0 | Z32: African Countries | AB32: =IFERROR(IF(OR(B32=0,B32=""),0,1),0) -> 0 | AC32: =IFERROR(IF(OR(C32="S",C32="D"),IF(AND(C32="D",D32="F"),1,IF(AND(C32="S",D32="M"),1,0)),IF(OR(C32="W",C32="H"),IF(OR(AND(C32="W",D32="F"),AND(C32="H",D32="M")),1,),IF(OR(D32="M",D32="F"),1,0))),0) -> 0 | AD32: =IFERROR(IF(OR(C32="E",C32="W",C32="H"),1,IF(C32 = "S",IF(D32="M",1,0),IF(D32 = "F",1,0))),0) -> 0 | AE32: =IFERROR(IF(OR(E32="M",E32="S"),IF(E32="M",IF(OR(C32="S",C32 = "D"),0,1),IF(OR(C32="W",C32="H"),0,1)),0),0) -> 0 | AF32: =IF(G32="",-1,IF(AND(G32<=TODAY(),ISNUMBER(DATE(YEAR(G32),MONTH(G32),DAY(G32)))),IF(AND(OR(C32="S",C32="D"),J32>24),-1,1),-1)) -> -1 | AG32: =IF(OR(I32="CAT 1",I32="CAT 2",I32="CAT 3",I32="CAT 4"),1,0) -> 0 | AH32: =PRODUCT(AF32:AG32)*AE32 -> 0
A33: 32 | J33: =IFERROR(IF(G33="","",ROUNDDOWN(IF($G33="","",(inception_date-$G33)/365.25),0)),0) | K33: =IF(I33="","",IF($AM$3=1,IFERROR(IF(J33=FALSE,"",VLOOKUP(J33,$AJ$1:$AK$18,2,1)),""),IFERROR(IF(J33 = "FALSE","",VLOOKUP(J33,#REF!,2,TRUE)),""))) | O33: =IF(C33="","",IF(R33=1,"Yes","No")) | P33: =IFERROR(IF(C33="","",IF(AND(Census!C33="E",Census!J33>=18,Census!J33<=65),"Yes","No")),"ERROR") | Q33: =IFERROR(IF(C33="","",IF(AND(Census!C33="E",Census!J33>=18,Census!J33<=64),"Yes","No")),"ERROR") | R33: =IF(OR(AB33<>1,AC33<>1,AD33<>1,AF33<>1,AE33<>1,AG33<>1),-1,1) -> -1 | S33: =AB33 -> 0 | T33: =AC33 -> 0 | U33: =AD33 -> 0 | V33: =AE33 -> 0 | W33: =AF33 -> -1 | X33: =AG33 -> 0 | Z33: Albanian | AB33: =IFERROR(IF(OR(B33=0,B33=""),0,1),0) -> 0 | AC33: =IFERROR(IF(OR(C33="S",C33="D"),IF(AND(C33="D",D33="F"),1,IF(AND(C33="S",D33="M"),1,0)),IF(OR(C33="W",C33="H"),IF(OR(AND(C33="W",D33="F"),AND(C33="H",D33="M")),1,),IF(OR(D33="M",D33="F"),1,0))),0) -> 0 | AD33: =IFERROR(IF(OR(C33="E",C33="W",C33="H"),1,IF(C33 = "S",IF(D33="M",1,0),IF(D33 = "F",1,0))),0) -> 0 | AE33: =IFERROR(IF(OR(E33="M",E33="S"),IF(E33="M",IF(OR(C33="S",C33 = "D"),0,1),IF(OR(C33="W",C33="H"),0,1)),0),0) -> 0 | AF33: =IF(G33="",-1,IF(AND(G33<=TODAY(),ISNUMBER(DATE(YEAR(G33),MONTH(G33),DAY(G33)))),IF(AND(OR(C33="S",C33="D"),J33>24),-1,1),-1)) -> -1 | AG33: =IF(OR(I33="CAT 1",I33="CAT 2",I33="CAT 3",I33="CAT 4"),1,0) -> 0 | AH33: =PRODUCT(AF33:AG33)*AE33 -> 0
A34: 33 | J34: =IFERROR(IF(G34="","",ROUNDDOWN(IF($G34="","",(inception_date-$G34)/365.25),0)),0) | K34: =IF(I34="","",IF($AM$3=1,IFERROR(IF(J34=FALSE,"",VLOOKUP(J34,$AJ$1:$AK$18,2,1)),""),IFERROR(IF(J34 = "FALSE","",VLOOKUP(J34,#REF!,2,TRUE)),""))) | O34: =IF(C34="","",IF(R34=1,"Yes","No")) | P34: =IFERROR(IF(C34="","",IF(AND(Census!C34="E",Census!J34>=18,Census!J34<=65),"Yes","No")),"ERROR") | Q34: =IFERROR(IF(C34="","",IF(AND(Census!C34="E",Census!J34>=18,Census!J34<=64),"Yes","No")),"ERROR") | R34: =IF(OR(AB34<>1,AC34<>1,AD34<>1,AF34<>1,AE34<>1,AG34<>1),-1,1) -> -1 | S34: =AB34 -> 0 | T34: =AC34 -> 0 | U34: =AD34 -> 0 | V34: =AE34 -> 0 | W34: =AF34 -> -1 | X34: =AG34 -> 0 | Z34: Algerian | AB34: =IFERROR(IF(OR(B34=0,B34=""),0,1),0) -> 0 | AC34: =IFERROR(IF(OR(C34="S",C34="D"),IF(AND(C34="D",D34="F"),1,IF(AND(C34="S",D34="M"),1,0)),IF(OR(C34="W",C34="H"),IF(OR(AND(C34="W",D34="F"),AND(C34="H",D34="M")),1,),IF(OR(D34="M",D34="F"),1,0))),0) -> 0 | AD34: =IFERROR(IF(OR(C34="E",C34="W",C34="H"),1,IF(C34 = "S",IF(D34="M",1,0),IF(D34 = "F",1,0))),0) -> 0 | AE34: =IFERROR(IF(OR(E34="M",E34="S"),IF(E34="M",IF(OR(C34="S",C34 = "D"),0,1),IF(OR(C34="W",C34="H"),0,1)),0),0) -> 0 | AF34: =IF(G34="",-1,IF(AND(G34<=TODAY(),ISNUMBER(DATE(YEAR(G34),MONTH(G34),DAY(G34)))),IF(AND(OR(C34="S",C34="D"),J34>24),-1,1),-1)) -> -1 | AG34: =IF(OR(I34="CAT 1",I34="CAT 2",I34="CAT 3",I34="CAT 4"),1,0) -> 0 | AH34: =PRODUCT(AF34:AG34)*AE34 -> 0
A35: 34 | J35: =IFERROR(IF(G35="","",ROUNDDOWN(IF($G35="","",(inception_date-$G35)/365.25),0)),0) | K35: =IF(I35="","",IF($AM$3=1,IFERROR(IF(J35=FALSE,"",VLOOKUP(J35,$AJ$1:$AK$18,2,1)),""),IFERROR(IF(J35 = "FALSE","",VLOOKUP(J35,#REF!,2,TRUE)),""))) | O35: =IF(C35="","",IF(R35=1,"Yes","No")) | P35: =IFERROR(IF(C35="","",IF(AND(Census!C35="E",Census!J35>=18,Census!J35<=65),"Yes","No")),"ERROR") | Q35: =IFERROR(IF(C35="","",IF(AND(Census!C35="E",Census!J35>=18,Census!J35<=64),"Yes","No")),"ERROR") | R35: =IF(OR(AB35<>1,AC35<>1,AD35<>1,AF35<>1,AE35<>1,AG35<>1),-1,1) -> -1 | S35: =AB35 -> 0 | T35: =AC35 -> 0 | U35: =AD35 -> 0 | V35: =AE35 -> 0 | W35: =AF35 -> -1 | X35: =AG35 -> 0 | Z35: American | AB35: =IFERROR(IF(OR(B35=0,B35=""),0,1),0) -> 0 | AC35: =IFERROR(IF(OR(C35="S",C35="D"),IF(AND(C35="D",D35="F"),1,IF(AND(C35="S",D35="M"),1,0)),IF(OR(C35="W",C35="H"),IF(OR(AND(C35="W",D35="F"),AND(C35="H",D35="M")),1,),IF(OR(D35="M",D35="F"),1,0))),0) -> 0 | AD35: =IFERROR(IF(OR(C35="E",C35="W",C35="H"),1,IF(C35 = "S",IF(D35="M",1,0),IF(D35 = "F",1,0))),0) -> 0 | AE35: =IFERROR(IF(OR(E35="M",E35="S"),IF(E35="M",IF(OR(C35="S",C35 = "D"),0,1),IF(OR(C35="W",C35="H"),0,1)),0),0) -> 0 | AF35: =IF(G35="",-1,IF(AND(G35<=TODAY(),ISNUMBER(DATE(YEAR(G35),MONTH(G35),DAY(G35)))),IF(AND(OR(C35="S",C35="D"),J35>24),-1,1),-1)) -> -1 | AG35: =IF(OR(I35="CAT 1",I35="CAT 2",I35="CAT 3",I35="CAT 4"),1,0) -> 0 | AH35: =PRODUCT(AF35:AG35)*AE35 -> 0
A36: 35 | J36: =IFERROR(IF(G36="","",ROUNDDOWN(IF($G36="","",(inception_date-$G36)/365.25),0)),0) | K36: =IF(I36="","",IF($AM$3=1,IFERROR(IF(J36=FALSE,"",VLOOKUP(J36,$AJ$1:$AK$18,2,1)),""),IFERROR(IF(J36 = "FALSE","",VLOOKUP(J36,#REF!,2,TRUE)),""))) | O36: =IF(C36="","",IF(R36=1,"Yes","No")) | P36: =IFERROR(IF(C36="","",IF(AND(Census!C36="E",Census!J36>=18,Census!J36<=65),"Yes","No")),"ERROR") | Q36: =IFERROR(IF(C36="","",IF(AND(Census!C36="E",Census!J36>=18,Census!J36<=64),"Yes","No")),"ERROR") | R36: =IF(OR(AB36<>1,AC36<>1,AD36<>1,AF36<>1,AE36<>1,AG36<>1),-1,1) -> -1 | S36: =AB36 -> 0 | T36: =AC36 -> 0 | U36: =AD36 -> 0 | V36: =AE36 -> 0 | W36: =AF36 -> -1 | X36: =AG36 -> 0 | Z36: American Samoan | AB36: =IFERROR(IF(OR(B36=0,B36=""),0,1),0) -> 0 | AC36: =IFERROR(IF(OR(C36="S",C36="D"),IF(AND(C36="D",D36="F"),1,IF(AND(C36="S",D36="M"),1,0)),IF(OR(C36="W",C36="H"),IF(OR(AND(C36="W",D36="F"),AND(C36="H",D36="M")),1,),IF(OR(D36="M",D36="F"),1,0))),0) -> 0 | AD36: =IFERROR(IF(OR(C36="E",C36="W",C36="H"),1,IF(C36 = "S",IF(D36="M",1,0),IF(D36 = "F",1,0))),0) -> 0 | AE36: =IFERROR(IF(OR(E36="M",E36="S"),IF(E36="M",IF(OR(C36="S",C36 = "D"),0,1),IF(OR(C36="W",C36="H"),0,1)),0),0) -> 0 | AF36: =IF(G36="",-1,IF(AND(G36<=TODAY(),ISNUMBER(DATE(YEAR(G36),MONTH(G36),DAY(G36)))),IF(AND(OR(C36="S",C36="D"),J36>24),-1,1),-1)) -> -1 | AG36: =IF(OR(I36="CAT 1",I36="CAT 2",I36="CAT 3",I36="CAT 4"),1,0) -> 0 | AH36: =PRODUCT(AF36:AG36)*AE36 -> 0
A37: 36 | J37: =IFERROR(IF(G37="","",ROUNDDOWN(IF($G37="","",(inception_date-$G37)/365.25),0)),0) | K37: =IF(I37="","",IF($AM$3=1,IFERROR(IF(J37=FALSE,"",VLOOKUP(J37,$AJ$1:$AK$18,2,1)),""),IFERROR(IF(J37 = "FALSE","",VLOOKUP(J37,#REF!,2,TRUE)),""))) | O37: =IF(C37="","",IF(R37=1,"Yes","No")) | P37: =IFERROR(IF(C37="","",IF(AND(Census!C37="E",Census!J37>=18,Census!J37<=65),"Yes","No")),"ERROR") | Q37: =IFERROR(IF(C37="","",IF(AND(Census!C37="E",Census!J37>=18,Census!J37<=64),"Yes","No")),"ERROR") | R37: =IF(OR(AB37<>1,AC37<>1,AD37<>1,AF37<>1,AE37<>1,AG37<>1),-1,1) -> -1 | S37: =AB37 -> 0 | T37: =AC37 -> 0 | U37: =AD37 -> 0 | V37: =AE37 -> 0 | W37: =AF37 -> -1 | X37: =AG37 -> 0 | Z37: Andorra | AB37: =IFERROR(IF(OR(B37=0,B37=""),0,1),0) -> 0 | AC37: =IFERROR(IF(OR(C37="S",C37="D"),IF(AND(C37="D",D37="F"),1,IF(AND(C37="S",D37="M"),1,0)),IF(OR(C37="W",C37="H"),IF(OR(AND(C37="W",D37="F"),AND(C37="H",D37="M")),1,),IF(OR(D37="M",D37="F"),1,0))),0) -> 0 | AD37: =IFERROR(IF(OR(C37="E",C37="W",C37="H"),1,IF(C37 = "S",IF(D37="M",1,0),IF(D37 = "F",1,0))),0) -> 0 | AE37: =IFERROR(IF(OR(E37="M",E37="S"),IF(E37="M",IF(OR(C37="S",C37 = "D"),0,1),IF(OR(C37="W",C37="H"),0,1)),0),0) -> 0 | AF37: =IF(G37="",-1,IF(AND(G37<=TODAY(),ISNUMBER(DATE(YEAR(G37),MONTH(G37),DAY(G37)))),IF(AND(OR(C37="S",C37="D"),J37>24),-1,1),-1)) -> -1 | AG37: =IF(OR(I37="CAT 1",I37="CAT 2",I37="CAT 3",I37="CAT 4"),1,0) -> 0 | AH37: =PRODUCT(AF37:AG37)*AE37 -> 0
A38: 37 | J38: =IFERROR(IF(G38="","",ROUNDDOWN(IF($G38="","",(inception_date-$G38)/365.25),0)),0) | K38: =IF(I38="","",IF($AM$3=1,IFERROR(IF(J38=FALSE,"",VLOOKUP(J38,$AJ$1:$AK$18,2,1)),""),IFERROR(IF(J38 = "FALSE","",VLOOKUP(J38,#REF!,2,TRUE)),""))) | O38: =IF(C38="","",IF(R38=1,"Yes","No")) | P38: =IFERROR(IF(C38="","",IF(AND(Census!C38="E",Census!J38>=18,Census!J38<=65),"Yes","No")),"ERROR") | Q38: =IFERROR(IF(C38="","",IF(AND(Census!C38="E",Census!J38>=18,Census!J38<=64),"Yes","No")),"ERROR") | R38: =IF(OR(AB38<>1,AC38<>1,AD38<>1,AF38<>1,AE38<>1,AG38<>1),-1,1) -> -1 | S38: =AB38 -> 0 | T38: =AC38 -> 0 | U38: =AD38 -> 0 | V38: =AE38 -> 0 | W38: =AF38 -> -1 | X38: =AG38 -> 0 | Z38: Angolan | AB38: =IFERROR(IF(OR(B38=0,B38=""),0,1),0) -> 0 | AC38: =IFERROR(IF(OR(C38="S",C38="D"),IF(AND(C38="D",D38="F"),1,IF(AND(C38="S",D38="M"),1,0)),IF(OR(C38="W",C38="H"),IF(OR(AND(C38="W",D38="F"),AND(C38="H",D38="M")),1,),IF(OR(D38="M",D38="F"),1,0))),0) -> 0 | AD38: =IFERROR(IF(OR(C38="E",C38="W",C38="H"),1,IF(C38 = "S",IF(D38="M",1,0),IF(D38 = "F",1,0))),0) -> 0 | AE38: =IFERROR(IF(OR(E38="M",E38="S"),IF(E38="M",IF(OR(C38="S",C38 = "D"),0,1),IF(OR(C38="W",C38="H"),0,1)),0),0) -> 0 | AF38: =IF(G38="",-1,IF(AND(G38<=TODAY(),ISNUMBER(DATE(YEAR(G38),MONTH(G38),DAY(G38)))),IF(AND(OR(C38="S",C38="D"),J38>24),-1,1),-1)) -> -1 | AG38: =IF(OR(I38="CAT 1",I38="CAT 2",I38="CAT 3",I38="CAT 4"),1,0) -> 0 | AH38: =PRODUCT(AF38:AG38)*AE38 -> 0
A39: 38 | J39: =IFERROR(IF(G39="","",ROUNDDOWN(IF($G39="","",(inception_date-$G39)/365.25),0)),0) | K39: =IF(I39="","",IF($AM$3=1,IFERROR(IF(J39=FALSE,"",VLOOKUP(J39,$AJ$1:$AK$18,2,1)),""),IFERROR(IF(J39 = "FALSE","",VLOOKUP(J39,#REF!,2,TRUE)),""))) | O39: =IF(C39="","",IF(R39=1,"Yes","No")) | P39: =IFERROR(IF(C39="","",IF(AND(Census!C39="E",Census!J39>=18,Census!J39<=65),"Yes","No")),"ERROR") | Q39: =IFERROR(IF(C39="","",IF(AND(Census!C39="E",Census!J39>=18,Census!J39<=64),"Yes","No")),"ERROR") | R39: =IF(OR(AB39<>1,AC39<>1,AD39<>1,AF39<>1,AE39<>1,AG39<>1),-1,1) -> -1 | S39: =AB39 -> 0 | T39: =AC39 -> 0 | U39: =AD39 -> 0 | V39: =AE39 -> 0 | W39: =AF39 -> -1 | X39: =AG39 -> 0 | Z39: Anguillian | AB39: =IFERROR(IF(OR(B39=0,B39=""),0,1),0) -> 0 | AC39: =IFERROR(IF(OR(C39="S",C39="D"),IF(AND(C39="D",D39="F"),1,IF(AND(C39="S",D39="M"),1,0)),IF(OR(C39="W",C39="H"),IF(OR(AND(C39="W",D39="F"),AND(C39="H",D39="M")),1,),IF(OR(D39="M",D39="F"),1,0))),0) -> 0 | AD39: =IFERROR(IF(OR(C39="E",C39="W",C39="H"),1,IF(C39 = "S",IF(D39="M",1,0),IF(D39 = "F",1,0))),0) -> 0 | AE39: =IFERROR(IF(OR(E39="M",E39="S"),IF(E39="M",IF(OR(C39="S",C39 = "D"),0,1),IF(OR(C39="W",C39="H"),0,1)),0),0) -> 0 | AF39: =IF(G39="",-1,IF(AND(G39<=TODAY(),ISNUMBER(DATE(YEAR(G39),MONTH(G39),DAY(G39)))),IF(AND(OR(C39="S",C39="D"),J39>24),-1,1),-1)) -> -1 | AG39: =IF(OR(I39="CAT 1",I39="CAT 2",I39="CAT 3",I39="CAT 4"),1,0) -> 0 | AH39: =PRODUCT(AF39:AG39)*AE39 -> 0
A40: 39 | J40: =IFERROR(IF(G40="","",ROUNDDOWN(IF($G40="","",(inception_date-$G40)/365.25),0)),0) | K40: =IF(I40="","",IF($AM$3=1,IFERROR(IF(J40=FALSE,"",VLOOKUP(J40,$AJ$1:$AK$18,2,1)),""),IFERROR(IF(J40 = "FALSE","",VLOOKUP(J40,#REF!,2,TRUE)),""))) | O40: =IF(C40="","",IF(R40=1,"Yes","No")) | P40: =IFERROR(IF(C40="","",IF(AND(Census!C40="E",Census!J40>=18,Census!J40<=65),"Yes","No")),"ERROR") | Q40: =IFERROR(IF(C40="","",IF(AND(Census!C40="E",Census!J40>=18,Census!J40<=64),"Yes","No")),"ERROR") | R40: =IF(OR(AB40<>1,AC40<>1,AD40<>1,AF40<>1,AE40<>1,AG40<>1),-1,1) -> -1 | S40: =AB40 -> 0 | T40: =AC40 -> 0 | U40: =AD40 -> 0 | V40: =AE40 -> 0 | W40: =AF40 -> -1 | X40: =AG40 -> 0 | Z40: Antarctica | AB40: =IFERROR(IF(OR(B40=0,B40=""),0,1),0) -> 0 | AC40: =IFERROR(IF(OR(C40="S",C40="D"),IF(AND(C40="D",D40="F"),1,IF(AND(C40="S",D40="M"),1,0)),IF(OR(C40="W",C40="H"),IF(OR(AND(C40="W",D40="F"),AND(C40="H",D40="M")),1,),IF(OR(D40="M",D40="F"),1,0))),0) -> 0 | AD40: =IFERROR(IF(OR(C40="E",C40="W",C40="H"),1,IF(C40 = "S",IF(D40="M",1,0),IF(D40 = "F",1,0))),0) -> 0 | AE40: =IFERROR(IF(OR(E40="M",E40="S"),IF(E40="M",IF(OR(C40="S",C40 = "D"),0,1),IF(OR(C40="W",C40="H"),0,1)),0),0) -> 0 | AF40: =IF(G40="",-1,IF(AND(G40<=TODAY(),ISNUMBER(DATE(YEAR(G40),MONTH(G40),DAY(G40)))),IF(AND(OR(C40="S",C40="D"),J40>24),-1,1),-1)) -> -1 | AG40: =IF(OR(I40="CAT 1",I40="CAT 2",I40="CAT 3",I40="CAT 4"),1,0) -> 0 | AH40: =PRODUCT(AF40:AG40)*AE40 -> 0
...
